Workbook

Sheet 全局参数
A1: 全局参数（辅助数据）—— 反推链的起点：只改目标与产出参数，全部公式自动重算
A3: 满级目标周期（天） | B3: 45 | C3: 设计目标：英雄培养完成（等级+升星+觉醒+装备强化）45 天
A4: 日产经验（折算企鹅） | B4: 150000 | C4: 玩家行为产出：体力刷图 + 企鹅兑换，数值为标准玩家日产出估算
A5: 经验递增率 | B5: 1.05 | C5: 每级所需经验等比递增（平滑成长曲线）
A6: 英雄等级上限 | B6: 60 | C6: 升级次数 = 上限 - 1 = 59
A7: 高级企鹅单只经验 | B7: 50000 | C7: 折算单位：日产经验 ÷ 企鹅经验 = 日产企鹅数
A8: 金币日产出 | B8: 400000 | C8: 副本 / 出售 / 任务（软通货主渠道）
A9: 觉醒大催化剂日产出 | B9: 1 | C9: 长线墙设计：催化剂是觉醒的节奏闸门
A10: 觉醒符文日产出 | B10: 40 | C10: 刷图掉落
A11: 升星金币基准（1→2星） | B11: 100000 | C11: 每升一星金币 ×2 递增
A12: 装备强化金币基准（+1） | B12: 8000 | C12: 每级 ×1.15 递增，+15 满级
A13: 装备部位数 | B13: 6 | C13: 武器/头盔/护甲/项链/戒指/鞋
A14: 培养完成度权重-等级 | B14: 0.35 | C14: 综合完成度 = 加权(等级/星级/觉醒/装备)
A15: 培养完成度权重-星级 | B15: 0.15
A16: 培养完成度权重-觉醒 | B16: 0.15
A17: 培养完成度权重-装备 | B17: 0.35
A19: 经验曲线和系数（59 级等比求和） | B19: =ROUND((POWER(全局参数!$B$5,59)-1)/(全局参数!$B$5-1),2) -> 335.79 | C19: Σ(1.05^k), k=0..58 —— 用于反推每级经验基准
A20: 每级经验基准（反推所得） | B20: =ROUND(全局参数!$B$3*全局参数!$B$4/全局参数!$B$19,0) -> 20102 | C20: 反推链核心：基准由目标周期与日产反推，改周期即改曲线

Sheet 等级经验表
A1: 等级经验表（每级所需经验 = 基准 × 递增率^(等级-1)，公式生成非手填）
A3: 等级区间 | B3: 所需经验 | C3: 累计经验 | D3: 折算高级企鹅
A4: 1→2 | B4: =ROUND(全局参数!$B$20*POWER(全局参数!$B$5,1-1),0) -> 20102 | C4: =B4 -> 20102 | D4: =ROUND(B4/全局参数!$B$7,1) -> 0.4
A5: 2→3 | B5: =ROUND(全局参数!$B$20*POWER(全局参数!$B$5,2-1),0) -> 21107 | C5: =C4+B5 -> 41209 | D5: =ROUND(B5/全局参数!$B$7,1) -> 0.4
A6: 3→4 | B6: =ROUND(全局参数!$B$20*POWER(全局参数!$B$5,3-1),0) -> 22162 | C6: =C5+B6 -> 63371 | D6: =ROUND(B6/全局参数!$B$7,1) -> 0.4
A7: 4→5 | B7: =ROUND(全局参数!$B$20*POWER(全局参数!$B$5,4-1),0) -> 23271 | C7: =C6+B7 -> 86642 | D7: =ROUND(B7/全局参数!$B$7,1) -> 0.5
A8: 5→6 | B8: =ROUND(全局参数!$B$20*POWER(全局参数!$B$5,5-1),0) -> 24434 | C8: =C7+B8 -> 111076 | D8: =ROUND(B8/全局参数!$B$7,1) -> 0.5
A9: 6→7 | B9: =ROUND(全局参数!$B$20*POWER(全局参数!$B$5,6-1),0) -> 25656 | C9: =C8+B9 -> 136732 | D9: =ROUND(B9/全局参数!$B$7,1) -> 0.5
A10: 7→8 | B10: =ROUND(全局参数!$B$20*POWER(全局参数!$B$5,7-1),0) -> 26939 | C10: =C9+B10 -> 163671 | D10: =ROUND(B10/全局参数!$B$7,1) -> 0.5
A11: 8→9 | B11: =ROUND(全局参数!$B$20*POWER(全局参数!$B$5,8-1),0) -> 28286 | C11: =C10+B11 -> 191957 | D11: =ROUND(B11/全局参数!$B$7,1) -> 0.6
A12: 9→10 | B12: =ROUND(全局参数!$B$20*POWER(全局参数!$B$5,9-1),0) -> 29700 | C12: =C11+B12 -> 221657 | D12: =ROUND(B12/全局参数!$B$7,1) -> 0.6
A13: 10→11 | B13: =ROUND(全局参数!$B$20*POWER(全局参数!$B$5,10-1),0) -> 31185 | C13: =C12+B13 -> 252842 | D13: =ROUND(B13/全局参数!$B$7,1) -> 0.6
A14: 11→12 | B14: =ROUND(全局参数!$B$20*POWER(全局参数!$B$5,11-1),0) -> 32744 | C14: =C13+B14 -> 285586 | D14: =ROUND(B14/全局参数!$B$7,1) -> 0.7
A15: 12→13 | B15: =ROUND(全局参数!$B$20*POWER(全局参数!$B$5,12-1),0) -> 34381 | C15: =C14+B15 -> 319967 | D15: =ROUND(B15/全局参数!$B$7,1) -> 0.7
A16: 13→14 | B16: =ROUND(全局参数!$B$20*POWER(全局参数!$B$5,13-1),0) -> 36100 | C16: =C15+B16 -> 356067 | D16: =ROUND(B16/全局参数!$B$7,1) -> 0.7
A17: 14→15 | B17: =ROUND(全局参数!$B$20*POWER(全局参数!$B$5,14-1),0) -> 37905 | C17: =C16+B17 -> 393972 | D17: =ROUND(B17/全局参数!$B$7,1) -> 0.8
A18: 15→16 | B18: =ROUND(全局参数!$B$20*POWER(全局参数!$B$5,15-1),0) -> 39801 | C18: =C17+B18 -> 433773 | D18: =ROUND(B18/全局参数!$B$7,1) -> 0.8
A19: 16→17 | B19: =ROUND(全局参数!$B$20*POWER(全局参数!$B$5,16-1),0) -> 41791 | C19: =C18+B19 -> 475564 | D19: =ROUND(B19/全局参数!$B$7,1) -> 0.8
A20: 17→18 | B20: =ROUND(全局参数!$B$20*POWER(全局参数!$B$5,17-1),0) -> 43880 | C20: =C19+B20 -> 519444 | D20: =ROUND(B20/全局参数!$B$7,1) -> 0.9
A21: 18→19 | B21: =ROUND(全局参数!$B$20*POWER(全局参数!$B$5,18-1),0) -> 46074 | C21: =C20+B21 -> 565518 | D21: =ROUND(B21/全局参数!$B$7,1) -> 0.9
A22: 19→20 | B22: =ROUND(全局参数!$B$20*POWER(全局参数!$B$5,19-1),0) -> 48378 | C22: =C21+B22 -> 613896 | D22: =ROUND(B22/全局参数!$B$7,1) -> 1
A23: 20→21 | B23: =ROUND(全局参数!$B$20*POWER(全局参数!$B$5,20-1),0) -> 50797 | C23: =C22+B23 -> 664693 | D23: =ROUND(B23/全局参数!$B$7,1) -> 1
A24: 21→22 | B24: =ROUND(全局参数!$B$20*POWER(全局参数!$B$5,21-1),0) -> 53337 | C24: =C23+B24 -> 718030 | D24: =ROUND(B24/全局参数!$B$7,1) -> 1.1
A25: 22→23 | B25: =ROUND(全局参数!$B$20*POWER(全局参数!$B$5,22-1),0) -> 56003 | C25: =C24+B25 -> 774033 | D25: =ROUND(B25/全局参数!$B$7,1) -> 1.1
A26: 23→24 | B26: =ROUND(全局参数!$B$20*POWER(全局参数!$B$5,23-1),0) -> 58804 | C26: =C25+B26 -> 832837 | D26: =ROUND(B26/全局参数!$B$7,1) -> 1.2
A27: 24→25 | B27: =ROUND(全局参数!$B$20*POWER(全局参数!$B$5,24-1),0) -> 61744 | C27: =C26+B27 -> 894581 | D27: =ROUND(B27/全局参数!$B$7,1) -> 1.2
A28: 25→26 | B28: =ROUND(全局参数!$B$20*POWER(全局参数!$B$5,25-1),0) -> 64831 | C28: =C27+B28 -> 959412 | D28: =ROUND(B28/全局参数!$B$7,1) -> 1.3
A29: 26→27 | B29: =ROUND(全局参数!$B$20*POWER(全局参数!$B$5,26-1),0) -> 68073 | C29: =C28+B29 -> 1027485 | D29: =ROUND(B29/全局参数!$B$7,1) -> 1.4
A30: 27→28 | B30: =ROUND(全局参数!$B$20*POWER(全局参数!$B$5,27-1),0) -> 71476 | C30: =C29+B30 -> 1098961 | D30: =ROUND(B30/全局参数!$B$7,1) -> 1.4
A31: 28→29 | B31: =ROUND(全局参数!$B$20*POWER(全局参数!$B$5,28-1),0) -> 75050 | C31: =C30+B31 -> 1174011 | D31: =ROUND(B31/全局参数!$B$7,1) -> 1.5
A32: 29→30 | B32: =ROUND(全局参数!$B$20*POWER(全局参数!$B$5,29-1),0) -> 78802 | C32: =C31+B32 -> 1252813 | D32: =ROUND(B32/全局参数!$B$7,1) -> 1.6
A33: 30→31 | B33: =ROUND(全局参数!$B$20*POWER(全局参数!$B$5,30-1),0) -> 82743 | C33: =C32+B33 -> 1335556 | D33: =ROUND(B33/全局参数!$B$7,1) -> 1.7
A34: 31→32 | B34: =ROUND(全局参数!$B$20*POWER(全局参数!$B$5,31-1),0) -> 86880 | C34: =C33+B34 -> 1422436 | D34: =ROUND(B34/全局参数!$B$7,1) -> 1.7
A35: 32→33 | B35: =ROUND(全局参数!$B$20*POWER(全局参数!$B$5,32-1),0) -> 91224 | C35: =C34+B35 -> 1513660 | D35: =ROUND(B35/全局参数!$B$7,1) -> 1.8
A36: 33→34 | B36: =ROUND(全局参数!$B$20*POWER(全局参数!$B$5,33-1),0) -> 95785 | C36: =C35+B36 -> 1609445 | D36: =ROUND(B36/全局参数!$B$7,1) -> 1.9
A37: 34→35 | B37: =ROUND(全局参数!$B$20*POWER(全局参数!$B$5,34-1),0) -> 100574 | C37: =C36+B37 -> 1710019 | D37: =ROUND(B37/全局参数!$B$7,1) -> 2
A38: 35→36 | B38: =ROUND(全局参数!$B$20*POWER(全局参数!$B$5,35-1),0) -> 105603 | C38: =C37+B38 -> 1815622 | D38: =ROUND(B38/全局参数!$B$7,1) -> 2.1
A39: 36→37 | B39: =ROUND(全局参数!$B$20*POWER(全局参数!$B$5,36-1),0) -> 110883 | C39: =C38+B39 -> 1926505 | D39: =ROUND(B39/全局参数!$B$7,1) -> 2.2
A40: 37→38 | B40: =ROUND(全局参数!$B$20*POWER(全局参数!$B$5,37-1),0) -> 116427 | C40: =C39+B40 -> 2042932 | D40: =ROUND(B40/全局参数!$B$7,1) -> 2.3
A41: 38→39 | B41: =ROUND(全局参数!$B$20*POWER(全局参数!$B$5,38-1),0) -> 122248 | C41: =C40+B41 -> 2165180 | D41: =ROUND(B41/全局参数!$B$7,1) -> 2.4
...

Sheet 升星表
A1: 升星表（金币 ×2 几何递增；幻影 ×3，养成节奏的中段墙）
A3: 星级阶段 | B3: 金币消耗 | C3: 材料说明
A4: 1星→2星 | B4: =全局参数!$B$11*POWER(2,0) -> 100000 | C4: 同星幻影 ×3（副本 / 商店获取）
A5: 2星→3星 | B5: =全局参数!$B$11*POWER(2,1) -> 200000 | C5: 同星幻影 ×3（副本 / 商店获取）
A6: 3星→4星 | B6: =全局参数!$B$11*POWER(2,2) -> 400000 | C6: 同星幻影 ×3（副本 / 商店获取）
A7: 4星→5星 | B7: =全局参数!$B$11*POWER(2,3) -> 800000 | C7: 同星幻影 ×3（副本 / 商店获取）
A8: 5星→6星 | B8: =全局参数!$B$11*POWER(2,4) -> 1600000 | C8: 同星幻影 ×3（副本 / 商店获取）
A9: 合计 | B9: =SUM(B4:B8) -> 3100000
A10: 升星总消耗 = 10+20+40+80+160 万 = 310 万金币。

Sheet 觉醒表
A1: 觉醒表（5 属性 × 5 阶 = 25 节点；大催化剂为节奏闸门）
A3: 觉醒阶 | B3: 属性 | C3: 符文消耗 | D3: 大催化剂 | E3: 节点效果
A4: 1阶 | B4: 攻击 | C4: =ROUND(10*POWER(2,0),0) -> 10 | D4: 1 | E4: 属性 +1.5%
A5: 1阶 | B5: 防御 | C5: =ROUND(10*POWER(2,0),0) -> 10 | D5: 1 | E5: 属性 +1.5%
A6: 1阶 | B6: 生命 | C6: =ROUND(10*POWER(2,0),0) -> 10 | D6: 1 | E6: 属性 +1.5%
A7: 1阶 | B7: 命中 | C7: =ROUND(10*POWER(2,0),0) -> 10 | D7: 1 | E7: 属性 +1.5%
A8: 1阶 | B8: 抵抗 | C8: =ROUND(10*POWER(2,0),0) -> 10 | D8: 1 | E8: 属性 +1.5%
A9: 2阶 | B9: 攻击 | C9: =ROUND(10*POWER(2,1),0) -> 20 | D9: 1 | E9: 属性 +3.0%
A10: 2阶 | B10: 防御 | C10: =ROUND(10*POWER(2,1),0) -> 20 | D10: 1 | E10: 属性 +3.0%
A11: 2阶 | B11: 生命 | C11: =ROUND(10*POWER(2,1),0) -> 20 | D11: 1 | E11: 属性 +3.0%
A12: 2阶 | B12: 命中 | C12: =ROUND(10*POWER(2,1),0) -> 20 | D12: 1 | E12: 属性 +3.0%
A13: 2阶 | B13: 抵抗 | C13: =ROUND(10*POWER(2,1),0) -> 20 | D13: 1 | E13: 属性 +3.0%
A14: 3阶 | B14: 攻击 | C14: =ROUND(10*POWER(2,2),0) -> 40 | D14: 1 | E14: 属性 +4.5%
A15: 3阶 | B15: 防御 | C15: =ROUND(10*POWER(2,2),0) -> 40 | D15: 1 | E15: 属性 +4.5%
A16: 3阶 | B16: 生命 | C16: =ROUND(10*POWER(2,2),0) -> 40 | D16: 1 | E16: 属性 +4.5%
A17: 3阶 | B17: 命中 | C17: =ROUND(10*POWER(2,2),0) -> 40 | D17: 1 | E17: 属性 +4.5%
A18: 3阶 | B18: 抵抗 | C18: =ROUND(10*POWER(2,2),0) -> 40 | D18: 1 | E18: 属性 +4.5%
A19: 4阶 | B19: 攻击 | C19: =ROUND(10*POWER(2,3),0) -> 80 | D19: 1 | E19: 属性 +6.0%
A20: 4阶 | B20: 防御 | C20: =ROUND(10*POWER(2,3),0) -> 80 | D20: 1 | E20: 属性 +6.0%
A21: 4阶 | B21: 生命 | C21: =ROUND(10*POWER(2,3),0) -> 80 | D21: 1 | E21: 属性 +6.0%
A22: 4阶 | B22: 命中 | C22: =ROUND(10*POWER(2,3),0) -> 80 | D22: 1 | E22: 属性 +6.0%
A23: 4阶 | B23: 抵抗 | C23: =ROUND(10*POWER(2,3),0) -> 80 | D23: 1 | E23: 属性 +6.0%
A24: 5阶 | B24: 攻击 | C24: =ROUND(10*POWER(2,4),0) -> 160 | D24: 1 | E24: 属性 +7.5%
A25: 5阶 | B25: 防御 | C25: =ROUND(10*POWER(2,4),0) -> 160 | D25: 1 | E25: 属性 +7.5%
A26: 5阶 | B26: 生命 | C26: =ROUND(10*POWER(2,4),0) -> 160 | D26: 1 | E26: 属性 +7.5%
A27: 5阶 | B27: 命中 | C27: =ROUND(10*POWER(2,4),0) -> 160 | D27: 1 | E27: 属性 +7.5%
A28: 5阶 | B28: 抵抗 | C28: =ROUND(10*POWER(2,4),0) -> 160 | D28: 1 | E28: 属性 +7.5%
A29: 合计 | C29: =SUM(C4:C28) -> 1550 | D29: =SUM(D4:D28) -> 25
A30: 大催化剂合计 25 个，日产出 1 个 → 觉醒为 25 天的长线墙（有意设计：等级快墙 / 觉醒长墙 / 装备无限墙 分层）。

Sheet 装备强化表
A1: 装备强化表（+1→+15，金币 ×1.15 几何递增；强化 100% 成功）
A3: 强化等级 | B3: 金币消耗（单件，品质系数=1）
A4: +1 | B4: =ROUND(全局参数!$B$12*POWER(1.15,0),0) -> 8000
A5: +2 | B5: =ROUND(全局参数!$B$12*POWER(1.15,1),0) -> 9200
A6: +3 | B6: =ROUND(全局参数!$B$12*POWER(1.15,2),0) -> 10580
A7: +4 | B7: =ROUND(全局参数!$B$12*POWER(1.15,3),0) -> 12167
A8: +5 | B8: =ROUND(全局参数!$B$12*POWER(1.15,4),0) -> 13992
A9: +6 | B9: =ROUND(全局参数!$B$12*POWER(1.15,5),0) -> 16091
A10: +7 | B10: =ROUND(全局参数!$B$12*POWER(1.15,6),0) -> 18504
A11: +8 | B11: =ROUND(全局参数!$B$12*POWER(1.15,7),0) -> 21280
A12: +9 | B12: =ROUND(全局参数!$B$12*POWER(1.15,8),0) -> 24472
A13: +10 | B13: =ROUND(全局参数!$B$12*POWER(1.15,9),0) -> 28143
A14: +11 | B14: =ROUND(全局参数!$B$12*POWER(1.15,10),0) -> 32364
A15: +12 | B15: =ROUND(全局参数!$B$12*POWER(1.15,11),0) -> 37219
A16: +13 | B16: =ROUND(全局参数!$B$12*POWER(1.15,12),0) -> 42802
A17: +14 | B17: =ROUND(全局参数!$B$12*POWER(1.15,13),0) -> 49222
A18: +15 | B18: =ROUND(全局参数!$B$12*POWER(1.15,14),0) -> 56606
A19: 单件合计(+15) | B19: =SUM(B4:B18) -> 380642
A20: 六件套合计 | B20: =B19*全局参数!$B$13 -> 2283852

Sheet 90天成长模拟
A1: 90 天成长模拟（标准玩家：日产出恒定，完成度 = 累计供给 ÷ 总需求）
A3: 天数 | B3: 等级完成度 | C3: 升星完成度 | D3: 觉醒完成度 | E3: 装备完成度 | F3: 综合完成度（加权）
A4: 1 | B4: =MIN(1,ROUND(1*全局参数!$B$4/等级经验表!$B$63,3)) -> 0.022 | C4: =MIN(1,ROUND(1*全局参数!$B$8*0.4/(升星表!$B$9+0.0001),3)) -> 0.052 | D4: =MIN(1,ROUND(1*全局参数!$B$9/(觉醒表!$D$29+0.0001),3)) -> 0.04 | E4: =MIN(1,ROUND(1*全局参数!$B$8*0.6/(装备强化表!$B$20+0.0001),3)) -> 0.105 | F4: =ROUND(0.35*C4+0.15*D4+0.15*E4+0.35*F4,3) -> 0
A5: 2 | B5: =MIN(1,ROUND(2*全局参数!$B$4/等级经验表!$B$63,3)) -> 0.044 | C5: =MIN(1,ROUND(2*全局参数!$B$8*0.4/(升星表!$B$9+0.0001),3)) -> 0.103 | D5: =MIN(1,ROUND(2*全局参数!$B$9/(觉醒表!$D$29+0.0001),3)) -> 0.08 | E5: =MIN(1,ROUND(2*全局参数!$B$8*0.6/(装备强化表!$B$20+0.0001),3)) -> 0.21 | F5: =ROUND(0.35*C5+0.15*D5+0.15*E5+0.35*F5,3) -> 0
A6: 3 | B6: =MIN(1,ROUND(3*全局参数!$B$4/等级经验表!$B$63,3)) -> 0.067 | C6: =MIN(1,ROUND(3*全局参数!$B$8*0.4/(升星表!$B$9+0.0001),3)) -> 0.155 | D6: =MIN(1,ROUND(3*全局参数!$B$9/(觉醒表!$D$29+0.0001),3)) -> 0.12 | E6: =MIN(1,ROUND(3*全局参数!$B$8*0.6/(装备强化表!$B$20+0.0001),3)) -> 0.315 | F6: =ROUND(0.35*C6+0.15*D6+0.15*E6+0.35*F6,3) -> 0
A7: 4 | B7: =MIN(1,ROUND(4*全局参数!$B$4/等级经验表!$B$63,3)) -> 0.089 | C7: =MIN(1,ROUND(4*全局参数!$B$8*0.4/(升星表!$B$9+0.0001),3)) -> 0.206 | D7: =MIN(1,ROUND(4*全局参数!$B$9/(觉醒表!$D$29+0.0001),3)) -> 0.16 | E7: =MIN(1,ROUND(4*全局参数!$B$8*0.6/(装备强化表!$B$20+0.0001),3)) -> 0.42 | F7: =ROUND(0.35*C7+0.15*D7+0.15*E7+0.35*F7,3) -> 0
A8: 5 | B8: =MIN(1,ROUND(5*全局参数!$B$4/等级经验表!$B$63,3)) -> 0.111 | C8: =MIN(1,ROUND(5*全局参数!$B$8*0.4/(升星表!$B$9+0.0001),3)) -> 0.258 | D8: =MIN(1,ROUND(5*全局参数!$B$9/(觉醒表!$D$29+0.0001),3)) -> 0.2 | E8: =MIN(1,ROUND(5*全局参数!$B$8*0.6/(装备强化表!$B$20+0.0001),3)) -> 0.525 | F8: =ROUND(0.35*C8+0.15*D8+0.15*E8+0.35*F8,3) -> 0
A9: 6 | B9: =MIN(1,ROUND(6*全局参数!$B$4/等级经验表!$B$63,3)) -> 0.133 | C9: =MIN(1,ROUND(6*全局参数!$B$8*0.4/(升星表!$B$9+0.0001),3)) -> 0.31 | D9: =MIN(1,ROUND(6*全局参数!$B$9/(觉醒表!$D$29+0.0001),3)) -> 0.24 | E9: =MIN(1,ROUND(6*全局参数!$B$8*0.6/(装备强化表!$B$20+0.0001),3)) -> 0.631 | F9: =ROUND(0.35*C9+0.15*D9+0.15*E9+0.35*F9,3) -> 0
A10: 7 | B10: =MIN(1,ROUND(7*全局参数!$B$4/等级经验表!$B$63,3)) -> 0.156 | C10: =MIN(1,ROUND(7*全局参数!$B$8*0.4/(升星表!$B$9+0.0001),3)) -> 0.361 | D10: =MIN(1,ROUND(7*全局参数!$B$9/(觉醒表!$D$29+0.0001),3)) -> 0.28 | E10: =MIN(1,ROUND(7*全局参数!$B$8*0.6/(装备强化表!$B$20+0.0001),3)) -> 0.736 | F10: =ROUND(0.35*C10+0.15*D10+0.15*E10+0.35*F10,3) -> 0
A11: 8 | B11: =MIN(1,ROUND(8*全局参数!$B$4/等级经验表!$B$63,3)) -> 0.178 | C11: =MIN(1,ROUND(8*全局参数!$B$8*0.4/(升星表!$B$9+0.0001),3)) -> 0.413 | D11: =MIN(1,ROUND(8*全局参数!$B$9/(觉醒表!$D$29+0.0001),3)) -> 0.32 | E11: =MIN(1,ROUND(8*全局参数!$B$8*0.6/(装备强化表!$B$20+0.0001),3)) -> 0.841 | F11: =ROUND(0.35*C11+0.15*D11+0.15*E11+0.35*F11,3) -> 0
A12: 9 | B12: =MIN(1,ROUND(9*全局参数!$B$4/等级经验表!$B$63,3)) -> 0.2 | C12: =MIN(1,ROUND(9*全局参数!$B$8*0.4/(升星表!$B$9+0.0001),3)) -> 0.465 | D12: =MIN(1,ROUND(9*全局参数!$B$9/(觉醒表!$D$29+0.0001),3)) -> 0.36 | E12: =MIN(1,ROUND(9*全局参数!$B$8*0.6/(装备强化表!$B$20+0.0001),3)) -> 0.946 | F12: =ROUND(0.35*C12+0.15*D12+0.15*E12+0.35*F12,3) -> 0
A13: 10 | B13: =MIN(1,ROUND(10*全局参数!$B$4/等级经验表!$B$63,3)) -> 0.222 | C13: =MIN(1,ROUND(10*全局参数!$B$8*0.4/(升星表!$B$9+0.0001),3)) -> 0.516 | D13: =MIN(1,ROUND(10*全局参数!$B$9/(觉醒表!$D$29+0.0001),3)) -> 0.4 | E13: =MIN(1,ROUND(10*全局参数!$B$8*0.6/(装备强化表!$B$20+0.0001),3)) -> 1 | F13: =ROUND(0.35*C13+0.15*D13+0.15*E13+0.35*F13,3) -> 0
A14: 11 | B14: =MIN(1,ROUND(11*全局参数!$B$4/等级经验表!$B$63,3)) -> 0.244 | C14: =MIN(1,ROUND(11*全局参数!$B$8*0.4/(升星表!$B$9+0.0001),3)) -> 0.568 | D14: =MIN(1,ROUND(11*全局参数!$B$9/(觉醒表!$D$29+0.0001),3)) -> 0.44 | E14: =MIN(1,ROUND(11*全局参数!$B$8*0.6/(装备强化表!$B$20+0.0001),3)) -> 1 | F14: =ROUND(0.35*C14+0.15*D14+0.15*E14+0.35*F14,3) -> 0
A15: 12 | B15: =MIN(1,ROUND(12*全局参数!$B$4/等级经验表!$B$63,3)) -> 0.267 | C15: =MIN(1,ROUND(12*全局参数!$B$8*0.4/(升星表!$B$9+0.0001),3)) -> 0.619 | D15: =MIN(1,ROUND(12*全局参数!$B$9/(觉醒表!$D$29+0.0001),3)) -> 0.48 | E15: =MIN(1,ROUND(12*全局参数!$B$8*0.6/(装备强化表!$B$20+0.0001),3)) -> 1 | F15: =ROUND(0.35*C15+0.15*D15+0.15*E15+0.35*F15,3) -> 0
A16: 13 | B16: =MIN(1,ROUND(13*全局参数!$B$4/等级经验表!$B$63,3)) -> 0.289 | C16: =MIN(1,ROUND(13*全局参数!$B$8*0.4/(升星表!$B$9+0.0001),3)) -> 0.671 | D16: =MIN(1,ROUND(13*全局参数!$B$9/(觉醒表!$D$29+0.0001),3)) -> 0.52 | E16: =MIN(1,ROUND(13*全局参数!$B$8*0.6/(装备强化表!$B$20+0.0001),3)) -> 1 | F16: =ROUND(0.35*C16+0.15*D16+0.15*E16+0.35*F16,3) -> 0
A17: 14 | B17: =MIN(1,ROUND(14*全局参数!$B$4/等级经验表!$B$63,3)) -> 0.311 | C17: =MIN(1,ROUND(14*全局参数!$B$8*0.4/(升星表!$B$9+0.0001),3)) -> 0.723 | D17: =MIN(1,ROUND(14*全局参数!$B$9/(觉醒表!$D$29+0.0001),3)) -> 0.56 | E17: =MIN(1,ROUND(14*全局参数!$B$8*0.6/(装备强化表!$B$20+0.0001),3)) -> 1 | F17: =ROUND(0.35*C17+0.15*D17+0.15*E17+0.35*F17,3) -> 0
A18: 15 | B18: =MIN(1,ROUND(15*全局参数!$B$4/等级经验表!$B$63,3)) -> 0.333 | C18: =MIN(1,ROUND(15*全局参数!$B$8*0.4/(升星表!$B$9+0.0001),3)) -> 0.774 | D18: =MIN(1,ROUND(15*全局参数!$B$9/(觉醒表!$D$29+0.0001),3)) -> 0.6 | E18: =MIN(1,ROUND(15*全局参数!$B$8*0.6/(装备强化表!$B$20+0.0001),3)) -> 1 | F18: =ROUND(0.35*C18+0.15*D18+0.15*E18+0.35*F18,3) -> 0
A19: 16 | B19: =MIN(1,ROUND(16*全局参数!$B$4/等级经验表!$B$63,3)) -> 0.356 | C19: =MIN(1,ROUND(16*全局参数!$B$8*0.4/(升星表!$B$9+0.0001),3)) -> 0.826 | D19: =MIN(1,ROUND(16*全局参数!$B$9/(觉醒表!$D$29+0.0001),3)) -> 0.64 | E19: =MIN(1,ROUND(16*全局参数!$B$8*0.6/(装备强化表!$B$20+0.0001),3)) -> 1 | F19: =ROUND(0.35*C19+0.15*D19+0.15*E19+0.35*F19,3) -> 0
A20: 17 | B20: =MIN(1,ROUND(17*全局参数!$B$4/等级经验表!$B$63,3)) -> 0.378 | C20: =MIN(1,ROUND(17*全局参数!$B$8*0.4/(升星表!$B$9+0.0001),3)) -> 0.877 | D20: =MIN(1,ROUND(17*全局参数!$B$9/(觉醒表!$D$29+0.0001),3)) -> 0.68 | E20: =MIN(1,ROUND(17*全局参数!$B$8*0.6/(装备强化表!$B$20+0.0001),3)) -> 1 | F20: =ROUND(0.35*C20+0.15*D20+0.15*E20+0.35*F20,3) -> 0
A21: 18 | B21: =MIN(1,ROUND(18*全局参数!$B$4/等级经验表!$B$63,3)) -> 0.4 | C21: =MIN(1,ROUND(18*全局参数!$B$8*0.4/(升星表!$B$9+0.0001),3)) -> 0.929 | D21: =MIN(1,ROUND(18*全局参数!$B$9/(觉醒表!$D$29+0.0001),3)) -> 0.72 | E21: =MIN(1,ROUND(18*全局参数!$B$8*0.6/(装备强化表!$B$20+0.0001),3)) -> 1 | F21: =ROUND(0.35*C21+0.15*D21+0.15*E21+0.35*F21,3) -> 0
A22: 19 | B22: =MIN(1,ROUND(19*全局参数!$B$4/等级经验表!$B$63,3)) -> 0.422 | C22: =MIN(1,ROUND(19*全局参数!$B$8*0.4/(升星表!$B$9+0.0001),3)) -> 0.981 | D22: =MIN(1,ROUND(19*全局参数!$B$9/(觉醒表!$D$29+0.0001),3)) -> 0.76 | E22: =MIN(1,ROUND(19*全局参数!$B$8*0.6/(装备强化表!$B$20+0.0001),3)) -> 1 | F22: =ROUND(0.35*C22+0.15*D22+0.15*E22+0.35*F22,3) -> 0
A23: 20 | B23: =MIN(1,ROUND(20*全局参数!$B$4/等级经验表!$B$63,3)) -> 0.444 | C23: =MIN(1,ROUND(20*全局参数!$B$8*0.4/(升星表!$B$9+0.0001),3)) -> 1 | D23: =MIN(1,ROUND(20*全局参数!$B$9/(觉醒表!$D$29+0.0001),3)) -> 0.8 | E23: =MIN(1,ROUND(20*全局参数!$B$8*0.6/(装备强化表!$B$20+0.0001),3)) -> 1 | F23: =ROUND(0.35*C23+0.15*D23+0.15*E23+0.35*F23,3) -> 0
A24: 21 | B24: =MIN(1,ROUND(21*全局参数!$B$4/等级经验表!$B$63,3)) -> 0.467 | C24: =MIN(1,ROUND(21*全局参数!$B$8*0.4/(升星表!$B$9+0.0001),3)) -> 1 | D24: =MIN(1,ROUND(21*全局参数!$B$9/(觉醒表!$D$29+0.0001),3)) -> 0.84 | E24: =MIN(1,ROUND(21*全局参数!$B$8*0.6/(装备强化表!$B$20+0.0001),3)) -> 1 | F24: =ROUND(0.35*C24+0.15*D24+0.15*E24+0.35*F24,3) -> 0
A25: 22 | B25: =MIN(1,ROUND(22*全局参数!$B$4/等级经验表!$B$63,3)) -> 0.489 | C25: =MIN(1,ROUND(22*全局参数!$B$8*0.4/(升星表!$B$9+0.0001),3)) -> 1 | D25: =MIN(1,ROUND(22*全局参数!$B$9/(觉醒表!$D$29+0.0001),3)) -> 0.88 | E25: =MIN(1,ROUND(22*全局参数!$B$8*0.6/(装备强化表!$B$20+0.0001),3)) -> 1 | F25: =ROUND(0.35*C25+0.15*D25+0.15*E25+0.35*F25,3) -> 0
A26: 23 | B26: =MIN(1,ROUND(23*全局参数!$B$4/等级经验表!$B$63,3)) -> 0.511 | C26: =MIN(1,ROUND(23*全局参数!$B$8*0.4/(升星表!$B$9+0.0001),3)) -> 1 | D26: =MIN(1,ROUND(23*全局参数!$B$9/(觉醒表!$D$29+0.0001),3)) -> 0.92 | E26: =MIN(1,ROUND(23*全局参数!$B$8*0.6/(装备强化表!$B$20+0.0001),3)) -> 1 | F26: =ROUND(0.35*C26+0.15*D26+0.15*E26+0.35*F26,3) -> 0
A27: 24 | B27: =MIN(1,ROUND(24*全局参数!$B$4/等级经验表!$B$63,3)) -> 0.533 | C27: =MIN(1,ROUND(24*全局参数!$B$8*0.4/(升星表!$B$9+0.0001),3)) -> 1 | D27: =MIN(1,ROUND(24*全局参数!$B$9/(觉醒表!$D$29+0.0001),3)) -> 0.96 | E27: =MIN(1,ROUND(24*全局参数!$B$8*0.6/(装备强化表!$B$20+0.0001),3)) -> 1 | F27: =ROUND(0.35*C27+0.15*D27+0.15*E27+0.35*F27,3) -> 0
A28: 25 | B28: =MIN(1,ROUND(25*全局参数!$B$4/等级经验表!$B$63,3)) -> 0.556 | C28: =MIN(1,ROUND(25*全局参数!$B$8*0.4/(升星表!$B$9+0.0001),3)) -> 1 | D28: =MIN(1,ROUND(25*全局参数!$B$9/(觉醒表!$D$29+0.0001),3)) -> 1 | E28: =MIN(1,ROUND(25*全局参数!$B$8*0.6/(装备强化表!$B$20+0.0001),3)) -> 1 | F28: =ROUND(0.35*C28+0.15*D28+0.15*E28+0.35*F28,3) -> 0
A29: 26 | B29: =MIN(1,ROUND(26*全局参数!$B$4/等级经验表!$B$63,3)) -> 0.578 | C29: =MIN(1,ROUND(26*全局参数!$B$8*0.4/(升星表!$B$9+0.0001),3)) -> 1 | D29: =MIN(1,ROUND(26*全局参数!$B$9/(觉醒表!$D$29+0.0001),3)) -> 1 | E29: =MIN(1,ROUND(26*全局参数!$B$8*0.6/(装备强化表!$B$20+0.0001),3)) -> 1 | F29: =ROUND(0.35*C29+0.15*D29+0.15*E29+0.35*F29,3) -> 0
A30: 27 | B30: =MIN(1,ROUND(27*全局参数!$B$4/等级经验表!$B$63,3)) -> 0.6 | C30: =MIN(1,ROUND(27*全局参数!$B$8*0.4/(升星表!$B$9+0.0001),3)) -> 1 | D30: =MIN(1,ROUND(27*全局参数!$B$9/(觉醒表!$D$29+0.0001),3)) -> 1 | E30: =MIN(1,ROUND(27*全局参数!$B$8*0.6/(装备强化表!$B$20+0.0001),3)) -> 1 | F30: =ROUND(0.35*C30+0.15*D30+0.15*E30+0.35*F30,3) -> 0
A31: 28 | B31: =MIN(1,ROUND(28*全局参数!$B$4/等级经验表!$B$63,3)) -> 0.622 | C31: =MIN(1,ROUND(28*全局参数!$B$8*0.4/(升星表!$B$9+0.0001),3)) -> 1 | D31: =MIN(1,ROUND(28*全局参数!$B$9/(觉醒表!$D$29+0.0001),3)) -> 1 | E31: =MIN(1,ROUND(28*全局参数!$B$8*0.6/(装备强化表!$B$20+0.0001),3)) -> 1 | F31: =ROUND(0.35*C31+0.15*D31+0.15*E31+0.35*F31,3) -> 0
A32: 29 | B32: =MIN(1,ROUND(29*全局参数!$B$4/等级经验表!$B$63,3)) -> 0.644 | C32: =MIN(1,ROUND(29*全局参数!$B$8*0.4/(升星表!$B$9+0.0001),3)) -> 1 | D32: =MIN(1,ROUND(29*全局参数!$B$9/(觉醒表!$D$29+0.0001),3)) -> 1 | E32: =MIN(1,ROUND(29*全局参数!$B$8*0.6/(装备强化表!$B$20+0.0001),3)) -> 1 | F32: =ROUND(0.35*C32+0.15*D32+0.15*E32+0.35*F32,3) -> 0
A33: 30 | B33: =MIN(1,ROUND(30*全局参数!$B$4/等级经验表!$B$63,3)) -> 0.667 | C33: =MIN(1,ROUND(30*全局参数!$B$8*0.4/(升星表!$B$9+0.0001),3)) -> 1 | D33: =MIN(1,ROUND(30*全局参数!$B$9/(觉醒表!$D$29+0.0001),3)) -> 1 | E33: =MIN(1,ROUND(30*全局参数!$B$8*0.6/(装备强化表!$B$20+0.0001),3)) -> 1 | F33: =ROUND(0.35*C33+0.15*D33+0.15*E33+0.35*F33,3) -> 0
A34: 31 | B34: =MIN(1,ROUND(31*全局参数!$B$4/等级经验表!$B$63,3)) -> 0.689 | C34: =MIN(1,ROUND(31*全局参数!$B$8*0.4/(升星表!$B$9+0.0001),3)) -> 1 | D34: =MIN(1,ROUND(31*全局参数!$B$9/(觉醒表!$D$29+0.0001),3)) -> 1 | E34: =MIN(1,ROUND(31*全局参数!$B$8*0.6/(装备强化表!$B$20+0.0001),3)) -> 1 | F34: =ROUND(0.35*C34+0.15*D34+0.15*E34+0.35*F34,3) -> 0
A35: 32 | B35: =MIN(1,ROUND(32*全局参数!$B$4/等级经验表!$B$63,3)) -> 0.711 | C35: =MIN(1,ROUND(32*全局参数!$B$8*0.4/(升星表!$B$9+0.0001),3)) -> 1 | D35: =MIN(1,ROUND(32*全局参数!$B$9/(觉醒表!$D$29+0.0001),3)) -> 1 | E35: =MIN(1,ROUND(32*全局参数!$B$8*0.6/(装备强化表!$B$20+0.0001),3)) -> 1 | F35: =ROUND(0.35*C35+0.15*D35+0.15*E35+0.35*F35,3) -> 0
A36: 33 | B36: =MIN(1,ROUND(33*全局参数!$B$4/等级经验表!$B$63,3)) -> 0.733 | C36: =MIN(1,ROUND(33*全局参数!$B$8*0.4/(升星表!$B$9+0.0001),3)) -> 1 | D36: =MIN(1,ROUND(33*全局参数!$B$9/(觉醒表!$D$29+0.0001),3)) -> 1 | E36: =MIN(1,ROUND(33*全局参数!$B$8*0.6/(装备强化表!$B$20+0.0001),3)) -> 1 | F36: =ROUND(0.35*C36+0.15*D36+0.15*E36+0.35*F36,3) -> 0
A37: 34 | B37: =MIN(1,ROUND(34*全局参数!$B$4/等级经验表!$B$63,3)) -> 0.756 | C37: =MIN(1,ROUND(34*全局参数!$B$8*0.4/(升星表!$B$9+0.0001),3)) -> 1 | D37: =MIN(1,ROUND(34*全局参数!$B$9/(觉醒表!$D$29+0.0001),3)) -> 1 | E37: =MIN(1,ROUND(34*全局参数!$B$8*0.6/(装备强化表!$B$20+0.0001),3)) -> 1 | F37: =ROUND(0.35*C37+0.15*D37+0.15*E37+0.35*F37,3) -> 0
A38: 35 | B38: =MIN(1,ROUND(35*全局参数!$B$4/等级经验表!$B$63,3)) -> 0.778 | C38: =MIN(1,ROUND(35*全局参数!$B$8*0.4/(升星表!$B$9+0.0001),3)) -> 1 | D38: =MIN(1,ROUND(35*全局参数!$B$9/(觉醒表!$D$29+0.0001),3)) -> 1 | E38: =MIN(1,ROUND(35*全局参数!$B$8*0.6/(装备强化表!$B$20+0.0001),3)) -> 1 | F38: =ROUND(0.35*C38+0.15*D38+0.15*E38+0.35*F38,3) -> 0
A39: 36 | B39: =MIN(1,ROUND(36*全局参数!$B$4/等级经验表!$B$63,3)) -> 0.8 | C39: =MIN(1,ROUND(36*全局参数!$B$8*0.4/(升星表!$B$9+0.0001),3)) -> 1 | D39: =MIN(1,ROUND(36*全局参数!$B$9/(觉醒表!$D$29+0.0001),3)) -> 1 | E39: =MIN(1,ROUND(36*全局参数!$B$8*0.6/(装备强化表!$B$20+0.0001),3)) -> 1 | F39: =ROUND(0.35*C39+0.15*D39+0.15*E39+0.35*F39,3) -> 0
A40: 37 | B40: =MIN(1,ROUND(37*全局参数!$B$4/等级经验表!$B$63,3)) -> 0.822 | C40: =MIN(1,ROUND(37*全局参数!$B$8*0.4/(升星表!$B$9+0.0001),3)) -> 1 | D40: =MIN(1,ROUND(37*全局参数!$B$9/(觉醒表!$D$29+0.0001),3)) -> 1 | E40: =MIN(1,ROUND(37*全局参数!$B$8*0.6/(装备强化表!$B$20+0.0001),3)) -> 1 | F40: =ROUND(0.35*C40+0.15*D40+0.15*E40+0.35*F40,3) -> 0
A41: 38 | B41: =MIN(1,ROUND(38*全局参数!$B$4/等级经验表!$B$63,3)) -> 0.844 | C41: =MIN(1,ROUND(38*全局参数!$B$8*0.4/(升星表!$B$9+0.0001),3)) -> 1 | D41: =MIN(1,ROUND(38*全局参数!$B$9/(觉醒表!$D$29+0.0001),3)) -> 1 | E41: =MIN(1,ROUND(38*全局参数!$B$8*0.6/(装备强化表!$B$20+0.0001),3)) -> 1 | F41: =ROUND(0.35*C41+0.15*D41+0.15*E41+0.35*F41,3) -> 0
...

Sheet 投放与周期校验
A1: 投放与周期校验（四条资源线：总需求 vs 目标周期内供给）
A3: 经验（升级） | B3: =等级经验表!$B$63 -> 6750137 | C3: =全局参数!$B$3*全局参数!$B$4 -> 6750000 | D3: =全局参数!$B$3*全局参数!$B$4 -> 6750000 | E3: =IF(C4>=B4,"✓ 达标","✗ 缺口 "&(B4-C4)) -> ✓ 达标
A4: 金币（升星+装备+觉醒） | B4: =升星表!$B$9+装备强化表!$B$20+觉醒表!$C$29*1000 -> 6933852 | C4: =全局参数!$B$3*全局参数!$B$8 -> 18000000 | D4: =全局参数!$B$3*全局参数!$B$8 -> 18000000 | E4: =IF(C5>=B5,"✓ 达标（结余转入长线装备养成）","✗ 缺口 "&(B5-C5)) -> ✓ 达标（结余转入长线装备养成）
A5: 觉醒大催化剂 | B5: =觉醒表!$D$29 -> 25 | C5: =全局参数!$B$3*全局参数!$B$9 -> 45 | D5: =全局参数!$B$3*全局参数!$B$9 -> 45 | E5: =IF(C6>=B6,"✓ 达标","✗ 缺口 "&(B6-C6)) -> ✓ 达标
A6: 觉醒符文 | B6: =觉醒表!$C$29 -> 1550 | C6: =全局参数!$B$3*全局参数!$B$10 -> 1800 | D6: =全局参数!$B$3*全局参数!$B$10 -> 1800 | E6: =IF(C7>=B7,"✓ 达标","✗ 缺口 "&(B7-C7)) -> ✓ 达标
A8: 说明：经验线按目标周期精确闭环；金币线大幅达标——结余是长线装备养成（副词条重铸）与多英雄培养的预算，符合"毕业≠终点"的品类设计。
A9: 演示：把满级目标周期 45 改为 30 → 经验校验立即显示缺口，需要上调日产或下调曲线基准——这就是可控性。

Sheet 方法论说明
A1: 内容
A2: ① 目标：满级培养周期 45 天（全局参数 B3）
A3: ② 反推：日产经验恒定 → 总经验预算 = 周期 × 日产 → 曲线基准 = 预算 ÷ 等比和系数（全局参数页反推公式）
A4: ③ 公式：等级经验表全列公式生成；升星/觉醒/装备消耗全部参数化
A5: ④ 校验：四条资源线（经验/金币/催化剂/符文）在【投放与周期校验】页闭环，改周期即全表重算
A6: ⑤ 曲线：90 天模拟页含培养完成度曲线（五条线），验证 45 天综合完成度 100%
A7: 分层墙设计：等级（快墙，随经验线性）→ 升星（中墙，金币×2 几何）→ 觉醒（长墙，催化剂 1/日闸门）→ 装备（无限墙，副词条驱动）
